<?xml version="1.0" ?>
<!-- =================================================================================== -->
<!-- |    This document was autogenerated by xacro from my_robot_integration.urdf.xacro | -->
<!-- |    EDITING THIS FILE BY HAND IS NOT RECOMMENDED                                 | -->
<!-- =================================================================================== -->
<!-- Name your robot here -->
<robot name="trial5_assembly">
  <link name="dummy_link"/>
  <joint name="dummy_link_joint" type="fixed">
    <parent link="dummy_link"/>
    <child link="base_link"/>
  </joint>
  <link name="base_link">
    <inertial>
      <origin rpy="0 0 0" xyz="1.1102E-16 1.3878E-17 -0.04"/>
      <mass value="0.828"/>
      <inertia ixx="0.050107" ixy="5.2948E-17" ixz="-2.1119E-18" iyy="0.68667" iyz="-7.2492E-19" izz="0.72312"/>
    </inertial>
    <visual>
      <origin rpy="0 0 0" xyz="0 0 0"/>
      <geometry>
        <mesh filename="package://trial5_assembly/meshes/base_link.STL"/>
      </geometry>
      <material name="">
        <color rgba="0.79216 0.81961 0.93333 1"/>
      </material>
    </visual>
    <collision>
      <origin rpy="0 0 0" xyz="0 0 0"/>
      <geometry>
        <mesh filename="package://trial5_assembly/meshes/base_link.STL"/>
      </geometry>
    </collision>
  </link>
  <link name="flt">
    <inertial>
      <origin rpy="0 0 0" xyz="0.14161 0.0014477 0.030036"/>
      <mass value="0.545"/>
      <inertia ixx="0.0012714" ixy="-0.00041074" ixz="-1.0645E-05" iyy="0.015623" iyz="6.4684E-07" izz="0.015912"/>
    </inertial>
    <visual>
      <origin rpy="0 0 0" xyz="0 0 0"/>
      <geometry>
        <mesh filename="package://trial5_assembly/meshes/flt.STL"/>
      </geometry>
      <material name="">
        <color rgba="0.79216 0.81961 0.93333 1"/>
      </material>
    </visual>
    <collision>
      <origin rpy="0 0 0" xyz="0 0 0"/>
      <geometry>
        <mesh filename="package://trial5_assembly/meshes/flt.STL"/>
      </geometry>
    </collision>
  </link>
  <joint name="fltj" type="continuous">
    <origin rpy="1.5708 0 3.1416" xyz="0.3 0.13 -0.04"/>
    <parent link="base_link"/>
    <child link="flt"/>
    <axis xyz="0 0 1"/>
  </joint>
  <link name="flk">
    <inertial>
      <origin rpy="0 0 0" xyz="-0.089186 -0.14524 0.030497"/>
      <mass value="0.47535"/>
      <inertia ixx="0.0062928" ixy="-0.0034406" ixz="1.8821E-05" iyy="0.00215" iyz="4.1847E-05" izz="0.0082896"/>
    </inertial>
    <visual>
      <origin rpy="0 0 0" xyz="0 0 0"/>
      <geometry>
        <mesh filename="package://trial5_assembly/meshes/flk.STL"/>
      </geometry>
      <material name="">
        <color rgba="0.79216 0.81961 0.93333 1"/>
      </material>
    </visual>
    <collision>
      <origin rpy="0 0 0" xyz="0 0 0"/>
      <geometry>
        <mesh filename="package://trial5_assembly/meshes/flk.STL"/>
      </geometry>
    </collision>
  </link>
  <joint name="flkj" type="continuous">
    <origin rpy="0 0 0" xyz="0.35615 -0.019942 0"/>
    <parent link="flt"/>
    <child link="flk"/>
    <axis xyz="0 0 1"/>
  </joint>
  <link name="flw">
    <inertial>
      <origin rpy="0 0 0" xyz="5.5511E-17 5.5511E-17 0.025"/>
      <mass value="0.2474"/>
      <inertia ixx="0.00015205" ixy="-3.7494E-40" ixz="-9.1833E-37" iyy="0.00015205" iyz="-4.9327E-37" izz="0.00020101"/>
    </inertial>
    <visual>
      <origin rpy="0 0 0" xyz="0 0 0"/>
      <geometry>
        <mesh filename="package://trial5_assembly/meshes/flw.STL"/>
      </geometry>
      <material name="">
        <color rgba="0.79216 0.81961 0.93333 1"/>
      </material>
    </visual>
    <collision>
      <origin rpy="0 0 0" xyz="0 0 0"/>
      <geometry>
        <mesh filename="package://trial5_assembly/meshes/flw.STL"/>
      </geometry>
    </collision>
  </link>
  <joint name="flwj" type="continuous">
    <origin rpy="0 0 0" xyz="-0.16905 -0.32271 0.06"/>
    <parent link="flk"/>
    <child link="flw"/>
    <axis xyz="0 0 1"/>
  </joint>
  <link name="frt">
    <inertial>
      <origin rpy="0 0 0" xyz="0.14161 0.0014477 -0.029964"/>
      <mass value="0.545"/>
      <inertia ixx="0.0012714" ixy="-0.00041074" ixz="-1.0645E-05" iyy="0.015623" iyz="6.4684E-07" izz="0.015912"/>
    </inertial>
    <visual>
      <origin rpy="0 0 0" xyz="0 0 0"/>
      <geometry>
        <mesh filename="package://trial5_assembly/meshes/frt.STL"/>
      </geometry>
      <material name="">
        <color rgba="0.79216 0.81961 0.93333 1"/>
      </material>
    </visual>
    <collision>
      <origin rpy="0 0 0" xyz="0 0 0"/>
      <geometry>
        <mesh filename="package://trial5_assembly/meshes/frt.STL"/>
      </geometry>
    </collision>
  </link>
  <joint name="frtj" type="continuous">
    <origin rpy="1.5708 0 3.1416" xyz="0.3 -0.13 -0.04"/>
    <parent link="base_link"/>
    <child link="frt"/>
    <axis xyz="0 0 1"/>
  </joint>
  <link name="frk">
    <inertial>
      <origin rpy="0 0 0" xyz="-0.089189 -0.14525 -0.030495"/>
      <mass value="0.47546"/>
      <inertia ixx="0.0062935" ixy="-0.0034404" ixz="-1.8805E-05" iyy="0.0021499" iyz="-4.1809E-05" izz="0.0082902"/>
    </inertial>
    <visual>
      <origin rpy="0 0 0" xyz="0 0 0"/>
      <geometry>
        <mesh filename="package://trial5_assembly/meshes/frk.STL"/>
      </geometry>
      <material name="">
        <color rgba="0.79216 0.81961 0.93333 1"/>
      </material>
    </visual>
    <collision>
      <origin rpy="0 0 0" xyz="0 0 0"/>
      <geometry>
        <mesh filename="package://trial5_assembly/meshes/frk.STL"/>
      </geometry>
    </collision>
  </link>
  <joint name="frkj" type="continuous">
    <origin rpy="0 0 0" xyz="0.35615 -0.019942 0"/>
    <parent link="frt"/>
    <child link="frk"/>
    <axis xyz="0 0 1"/>
  </joint>
  <link name="frw">
    <inertial>
      <origin rpy="0 0 0" xyz="5.5511E-17 5.5511E-17 -0.025"/>
      <mass value="0.2474"/>
      <inertia ixx="0.00015205" ixy="-3.7494E-40" ixz="-8.8233E-23" iyy="0.00015205" iyz="-4.9327E-37" izz="0.00020101"/>
    </inertial>
    <visual>
      <origin rpy="0 0 0" xyz="0 0 0"/>
      <geometry>
        <mesh filename="package://trial5_assembly/meshes/frw.STL"/>
      </geometry>
      <material name="">
        <color rgba="0.79216 0.81961 0.93333 1"/>
      </material>
    </visual>
    <collision>
      <origin rpy="0 0 0" xyz="0 0 0"/>
      <geometry>
        <mesh filename="package://trial5_assembly/meshes/frw.STL"/>
      </geometry>
    </collision>
  </link>
  <joint name="frwj" type="continuous">
    <origin rpy="0 0 0" xyz="-0.16905 -0.32271 -0.06"/>
    <parent link="frk"/>
    <child link="frw"/>
    <axis xyz="0 0 1"/>
  </joint>
  <link name="blt">
    <inertial>
      <origin rpy="0 0 0" xyz="0.14161 0.0014477 0.030036"/>
      <mass value="0.545"/>
      <inertia ixx="0.0012714" ixy="-0.00041074" ixz="-1.0645E-05" iyy="0.015623" iyz="6.4684E-07" izz="0.015912"/>
    </inertial>
    <visual>
      <origin rpy="0 0 0" xyz="0 0 0"/>
      <geometry>
        <mesh filename="package://trial5_assembly/meshes/blt.STL"/>
      </geometry>
      <material name="">
        <color rgba="0.79216 0.81961 0.93333 1"/>
      </material>
    </visual>
    <collision>
      <origin rpy="0 0 0" xyz="0 0 0"/>
      <geometry>
        <mesh filename="package://trial5_assembly/meshes/blt.STL"/>
      </geometry>
    </collision>
  </link>
  <joint name="bltj" type="continuous">
    <origin rpy="1.5708 0 3.1416" xyz="-0.3 0.13 -0.04"/>
    <parent link="base_link"/>
    <child link="blt"/>
    <axis xyz="0 0 1"/>
  </joint>
  <link name="blk">
    <inertial>
      <origin rpy="0 0 0" xyz="-0.089186 -0.14524 0.030497"/>
      <mass value="0.47535"/>
      <inertia ixx="0.0062928" ixy="-0.0034406" ixz="1.8821E-05" iyy="0.00215" iyz="4.1847E-05" izz="0.0082896"/>
    </inertial>
    <visual>
      <origin rpy="0 0 0" xyz="0 0 0"/>
      <geometry>
        <mesh filename="package://trial5_assembly/meshes/blk.STL"/>
      </geometry>
      <material name="">
        <color rgba="0.79216 0.81961 0.93333 1"/>
      </material>
    </visual>
    <collision>
      <origin rpy="0 0 0" xyz="0 0 0"/>
      <geometry>
        <mesh filename="package://trial5_assembly/meshes/blk.STL"/>
      </geometry>
    </collision>
  </link>
  <joint name="blkj" type="continuous">
    <origin rpy="0 0 0" xyz="0.35615 -0.019942 0"/>
    <parent link="blt"/>
    <child link="blk"/>
    <axis xyz="0 0 1"/>
  </joint>
  <link name="blw">
    <inertial>
      <origin rpy="0 0 0" xyz="0 0 0.025"/>
      <mass value="0.2474"/>
      <inertia ixx="0.00015205" ixy="-3.7494E-40" ixz="1.1479E-39" iyy="0.00015205" iyz="-4.9327E-37" izz="0.00020101"/>
    </inertial>
    <visual>
      <origin rpy="0 0 0" xyz="0 0 0"/>
      <geometry>
        <mesh filename="package://trial5_assembly/meshes/blw.STL"/>
      </geometry>
      <material name="">
        <color rgba="0.79216 0.81961 0.93333 1"/>
      </material>
    </visual>
    <collision>
      <origin rpy="0 0 0" xyz="0 0 0"/>
      <geometry>
        <mesh filename="package://trial5_assembly/meshes/blw.STL"/>
      </geometry>
    </collision>
  </link>
  <joint name="blwj" type="continuous">
    <origin rpy="0 0 0" xyz="-0.16905 -0.32271 0.06"/>
    <parent link="blk"/>
    <child link="blw"/>
    <axis xyz="0 0 1"/>
  </joint>
  <link name="brt">
    <inertial>
      <origin rpy="0 0 0" xyz="0.14161 0.0014477 -0.029964"/>
      <mass value="0.545"/>
      <inertia ixx="0.0012714" ixy="-0.00041074" ixz="-1.0645E-05" iyy="0.015623" iyz="6.4684E-07" izz="0.015912"/>
    </inertial>
    <visual>
      <origin rpy="0 0 0" xyz="0 0 0"/>
      <geometry>
        <mesh filename="package://trial5_assembly/meshes/brt.STL"/>
      </geometry>
      <material name="">
        <color rgba="0.79216 0.81961 0.93333 1"/>
      </material>
    </visual>
    <collision>
      <origin rpy="0 0 0" xyz="0 0 0"/>
      <geometry>
        <mesh filename="package://trial5_assembly/meshes/brt.STL"/>
      </geometry>
    </collision>
  </link>
  <joint name="brtj" type="continuous">
    <origin rpy="1.5708 0 3.1416" xyz="-0.3 -0.13 -0.04"/>
    <parent link="base_link"/>
    <child link="brt"/>
    <axis xyz="0 0 1"/>
  </joint>
  <link name="brk">
    <inertial>
      <origin rpy="0 0 0" xyz="-0.089189 -0.14525 -0.030495"/>
      <mass value="0.47546"/>
      <inertia ixx="0.0062935" ixy="-0.0034404" ixz="-1.8805E-05" iyy="0.0021499" iyz="-4.1809E-05" izz="0.0082902"/>
    </inertial>
    <visual>
      <origin rpy="0 0 0" xyz="0 0 0"/>
      <geometry>
        <mesh filename="package://trial5_assembly/meshes/brk.STL"/>
      </geometry>
      <material name="">
        <color rgba="0.79216 0.81961 0.93333 1"/>
      </material>
    </visual>
    <collision>
      <origin rpy="0 0 0" xyz="0 0 0"/>
      <geometry>
        <mesh filename="package://trial5_assembly/meshes/brk.STL"/>
      </geometry>
    </collision>
  </link>
  <joint name="brkj" type="continuous">
    <origin rpy="0 0 0" xyz="0.35615 -0.019942 0"/>
    <parent link="brt"/>
    <child link="brk"/>
    <axis xyz="0 0 1"/>
  </joint>
  <link name="brw">
    <inertial>
      <origin rpy="0 0 0" xyz="1.1102E-16 5.5511E-17 -0.025"/>
      <mass value="0.2474"/>
      <inertia ixx="0.00015205" ixy="-3.7494E-40" ixz="8.8233E-23" iyy="0.00015205" iyz="-4.9327E-37" izz="0.00020101"/>
    </inertial>
    <visual>
      <origin rpy="0 0 0" xyz="0 0 0"/>
      <geometry>
        <mesh filename="package://trial5_assembly/meshes/brw.STL"/>
      </geometry>
      <material name="">
        <color rgba="0.79216 0.81961 0.93333 1"/>
      </material>
    </visual>
    <collision>
      <origin rpy="0 0 0" xyz="0 0 0"/>
      <geometry>
        <mesh filename="package://trial5_assembly/meshes/brw.STL"/>
      </geometry>
    </collision>
  </link>
  <joint name="brwj" type="continuous">
    <origin rpy="0 0 0" xyz="-0.16905 -0.32271 -0.06"/>
    <parent link="brk"/>
    <child link="brw"/>
    <axis xyz="0 0 1"/>
  </joint>
  <!--  Gazebo plugin for control here is already added for you -->
  <gazebo>
    <plugin filename="libgazebo_ros_control.so" name="gazebo_ros_control">
      <robotNamespace>/trial5_assembly</robotNamespace>
      <robotSimType>gazebo_ros_control/DefaultRobotHWSim</robotSimType>
      <legacyModeNS>true</legacyModeNS>
    </plugin>
  </gazebo>
  <transmission name="tran1">
    <type>transmission_interface/SimpleTransmission</type>
    <joint name="flwj">
      <hardwareInterface>hardware_interface/VelocityJointInterface</hardwareInterface>
    </joint>
    <actuator name="motor1">
      <hardwareInterface>hardware_interface/VelocityJointInterface</hardwareInterface>
      <mechanicalReduction>1</mechanicalReduction>
    </actuator>
  </transmission>
  <transmission name="tran1">
    <type>transmission_interface/SimpleTransmission</type>
    <joint name="fltj">
      <hardwareInterface>hardware_interface/EffortJointInterface</hardwareInterface>
    </joint>
    <actuator name="motor2">
      <hardwareInterface>hardware_interface/EffortJointInterface</hardwareInterface>
      <mechanicalReduction>1</mechanicalReduction>
    </actuator>
  </transmission>
  <transmission name="tran1">
    <type>transmission_interface/SimpleTransmission</type>
    <joint name="flkj">
      <hardwareInterface>hardware_interface/EffortJointInterface</hardwareInterface>
    </joint>
    <actuator name="motor3">
      <hardwareInterface>hardware_interface/EffortJointInterface</hardwareInterface>
      <mechanicalReduction>1</mechanicalReduction>
    </actuator>
  </transmission>
  <transmission name="tran1">
    <type>transmission_interface/SimpleTransmission</type>
    <joint name="frwj">
      <hardwareInterface>hardware_interface/VelocityJointInterface</hardwareInterface>
    </joint>
    <actuator name="motor4">
      <hardwareInterface>hardware_interface/VelocityJointInterface</hardwareInterface>
      <mechanicalReduction>1</mechanicalReduction>
    </actuator>
  </transmission>
  <transmission name="tran1">
    <type>transmission_interface/SimpleTransmission</type>
    <joint name="frtj">
      <hardwareInterface>hardware_interface/EffortJointInterface</hardwareInterface>
    </joint>
    <actuator name="motor5">
      <hardwareInterface>hardware_interface/EffortJointInterface</hardwareInterface>
      <mechanicalReduction>1</mechanicalReduction>
    </actuator>
  </transmission>
  <transmission name="tran1">
    <type>transmission_interface/SimpleTransmission</type>
    <joint name="frkj">
      <hardwareInterface>hardware_interface/EffortJointInterface</hardwareInterface>
    </joint>
    <actuator name="motor6">
      <hardwareInterface>hardware_interface/EffortJointInterface</hardwareInterface>
      <mechanicalReduction>1</mechanicalReduction>
    </actuator>
  </transmission>
  <transmission name="tran1">
    <type>transmission_interface/SimpleTransmission</type>
    <joint name="blwj">
      <hardwareInterface>hardware_interface/VelocityJointInterface</hardwareInterface>
    </joint>
    <actuator name="motor7">
      <hardwareInterface>hardware_interface/VelocityJointInterface</hardwareInterface>
      <mechanicalReduction>1</mechanicalReduction>
    </actuator>
  </transmission>
  <transmission name="tran1">
    <type>transmission_interface/SimpleTransmission</type>
    <joint name="bltj">
      <hardwareInterface>hardware_interface/EffortJointInterface</hardwareInterface>
    </joint>
    <actuator name="motor8">
      <hardwareInterface>hardware_interface/EffortJointInterface</hardwareInterface>
      <mechanicalReduction>1</mechanicalReduction>
    </actuator>
  </transmission>
  <transmission name="tran1">
    <type>transmission_interface/SimpleTransmission</type>
    <joint name="blkj">
      <hardwareInterface>hardware_interface/EffortJointInterface</hardwareInterface>
    </joint>
    <actuator name="motor9">
      <hardwareInterface>hardware_interface/EffortJointInterface</hardwareInterface>
      <mechanicalReduction>1</mechanicalReduction>
    </actuator>
  </transmission>
  <transmission name="tran1">
    <type>transmission_interface/SimpleTransmission</type>
    <joint name="brwj">
      <hardwareInterface>hardware_interface/VelocityJointInterface</hardwareInterface>
    </joint>
    <actuator name="motor10">
      <hardwareInterface>hardware_interface/VelocityJointInterface</hardwareInterface>
      <mechanicalReduction>1</mechanicalReduction>
    </actuator>
  </transmission>
  <transmission name="tran1">
    <type>transmission_interface/SimpleTransmission</type>
    <joint name="brtj">
      <hardwareInterface>hardware_interface/EffortJointInterface</hardwareInterface>
    </joint>
    <actuator name="motor11">
      <hardwareInterface>hardware_interface/EffortJointInterface</hardwareInterface>
      <mechanicalReduction>1</mechanicalReduction>
    </actuator>
  </transmission>
  <transmission name="tran1">
    <type>transmission_interface/SimpleTransmission</type>
    <joint name="brkj">
      <hardwareInterface>hardware_interface/EffortJointInterface</hardwareInterface>
    </joint>
    <actuator name="motor12">
      <hardwareInterface>hardware_interface/EffortJointInterface</hardwareInterface>
      <mechanicalReduction>1</mechanicalReduction>
    </actuator>
  </transmission>
  <link name="base_laser">
    <inertial>
      <origin rpy="0 0 0" xyz="-0.00029774 0.0066667 0.00013047"/>
      <mass value="0.15717"/>
      <inertia ixx="6.7885E-05" ixy="-1.3987E-07" ixz="-8.1554E-07" iyy="0.00013173" iyz="-9.0932E-08" izz="7.1972E-05"/>
    </inertial>
    <visual>
      <origin rpy="0 0 0" xyz="0 0 0"/>
      <geometry>
        <mesh filename="package://ydlidar_ros/meshes/ydlidar.dae"/>
      </geometry>
      <material name="">
        <color rgba="0.64706 0.61961 0.58824 1"/>
      </material>
    </visual>
    <collision>
      <origin rpy="0 0 0" xyz="0 0 0"/>
      <geometry>
        <mesh filename="package://ydlidar_ros/meshes/ydlidar.dae"/>
      </geometry>
    </collision>
  </link>
  <link name="laser_frame">
    <inertial>
      <origin rpy="0 0 0" xyz="-0.00036659 0.00064155 -0.00027052"/>
      <mass value="0.25482"/>
      <inertia ixx="8.9194E-05" ixy="1.8116E-07" ixz="3.6435E-08" iyy="0.00018279" iyz="2.423E-07" izz="0.00011103"/>
    </inertial>
    <!--visual>
      <origin
        xyz="0 0 0"
        rpy="0 0 0" />
      <geometry>
        <mesh
          filename="package://ydlidar_ros/meshes/ydlidar.dae" />
      </geometry>
      <material
        name="">
        <color
          rgba="0.64706 0.61961 0.58824 1" />
      </material>
    </visual-->
    <!--collision>
      <origin
        xyz="0 0 0"
        rpy="0 0 0" />
      <geometry>
        <mesh
          filename="package://ydlidar_ros/meshes/ydlidar.dae" />
      </geometry>
    </collision-->
  </link>
  <joint name="laser_joint" type="fixed">
    <origin rpy="0 0 0" xyz="0 0 0.03172"/>
    <parent link="base_laser"/>
    <child link="laser_frame"/>
    <axis xyz="0 0 0"/>
  </joint>
  <!-- Add your gazebo sensors here -->
  <gazebo reference="base_laser">
    <!-- <gravity>true</gravity> -->
    <!-- Gazebo has fixed set of Sensors types. Check them out here <> -->
    <sensor name="laser" type="ray">
      <!-- Add in your sensor characteristics -->
      <pose> 0 0 0 0 0 0 </pose>
      <visualise>true</visualise>
      <update_rate>40</update_rate>
      <!-- <always_on>true</always_on> -->
      <ray>
        <scan>
          <horizontal>
            <samples>720</samples>
            <resolution>1</resolution>
            <min_angle>-1.570796</min_angle>
            <max_angle>1.570796</max_angle>
          </horizontal>
        </scan>
        <range>
          <min>0.10</min>
          <max>30.0</max>
          <resolution>0.01</resolution>
        </range>
        <noise>
          <type>gaussian</type>
          <mean>0.0</mean>
          <stddev>0.01</stddev>
        </noise>
      </ray>
      <plugin filename="libgazebo_ros_laser.so" name="gazebo_ros_head_hokuyo_controller">
        <!-- Use topic name as /my_robot/scan -->
        <topicName>/trial5_assembly/scan</topicName>
        <frameName>laser_frame</frameName>
      </plugin>
    </sensor>
  </gazebo>
  <!-- Gazebo plugin for control here is already added for you -->
  <!-- <gazebo>
		<plugin name="gazebo_ros_control" filename="libgazebo_ros_control.so">
			<robotNamespace>/robot_fourwheel</robotNamespace>
			<robotSimType>gazebo_ros_control/DefaultRobotHWSim</robotSimType>
			<legacyModeNS>true</legacyModeNS>
		</plugin>
	</gazebo> -->
  <!-- Create a joint between your robot and sensor -->
  <joint name="lidar_laser_joint" type="fixed">
    <axis xyz="0 0 1"/>
    <origin rpy="0 0 0" xyz="0.48 0 0.132"/>
    <parent link="dummy_link"/>
    <child link="base_laser"/>
  </joint>
</robot>
